<?xml version="1.0" ?>
<!-- =================================================================================== -->
<!-- |    This document was autogenerated by xacro from urdf/carModel.xacro            | -->
<!-- |    EDITING THIS FILE BY HAND IS NOT RECOMMENDED                                 | -->
<!-- =================================================================================== -->
<robot name="car_model" xmlns:xacro="http://www.ros.org/wiki/xacro">
  <material name="black">
    <color rgba="0 0 0 1"/>
  </material>
  <material name="blue">
    <color rgba="0 0 0.8 1"/>
  </material>
  <material name="white">
    <color rgba="1 1 1 1"/>
  </material>
  <material name="gray">
    <color rgba="0.3 0.3 0.3 1"/>
  </material>
  <link name="base_footprint">
    <visual>
      <geometry>
        <box size="0.001 0.001 0.001"/>
      </geometry>
      <origin rpy="0 0 0" xyz="0 0 0"/>
    </visual>
    <collision>
      <geometry>
        <box size="0.001 0.001 0.001"/>
      </geometry>
      <origin rpy="0 0 0" xyz="0 0 0"/>
    </collision>
    <inertial>
      <mass value="0.0001"/>
      <inertia ixx="1.0" ixy="0.0" ixz="0.0" iyy="1.0" iyz="0.0" izz="1.0"/>
    </inertial>
  </link>
  <gazebo reference="base_footprint">
    <material>Gazebo/Green</material>
  </gazebo>
  <link name="base_link">
    <visual>
      <geometry>
        <box size="0.25 0.5 0.0625"/>
      </geometry>
      <material name="black"/>
      <origin rpy="0 0 0" xyz="0 0 0.125"/>
    </visual>
    <collision>
      <geometry>
        <box size="0.25 0.5 0.0625"/>
      </geometry>
      <origin rpy="0 0 0" xyz="0 0 0.125"/>
    </collision>
    <inertial>
      <mass value="15"/>
      <inertia ixx="1.0" ixy="0.0" ixz="0.0" iyy="1.0" iyz="0.0" izz="1.0"/>
    </inertial>
  </link>
  <joint name="base_footprint_joint" type="fixed">
    <axis xyz="0 0 1"/>
    <origin xyz="0 0 0"/>
    <parent link="base_footprint"/>
    <child link="base_link"/>
  </joint>
  <gazebo reference="base_link">
    <material>Gazebo/Black</material>
  </gazebo>
  <link name="camera">
    <visual>
      <geometry>
        <box size="0.1 0.1 0.1"/>
      </geometry>
      <material name="black"/>
    </visual>
    <collision>
      <geometry>
        <box size="0.1 0.1 0.1"/>
      </geometry>
    </collision>
    <inertial>
      <mass value="1e-05"/>
      <inertia ixx="1.0" ixy="0.0" ixz="0.0" iyy="1.0" iyz="0.0" izz="1.0"/>
    </inertial>
  </link>
  <joint name="camera_joint" type="continuous">
    <origin rpy="-1.57 -1.57 1.57" xyz="0 0.375 0.1875"/>
    <parent link="base_footprint"/>
    <child link="camera"/>
  </joint>
  <gazebo reference="camera">
    <material>Gazebo/Black</material>
    <sensor name="car_model_camera" type="camera">
      <update_rate>33.3</update_rate>
      <camera name="camera">
        <horizontal_fov>1.3962634</horizontal_fov>
        <image>
          <width>640</width>
          <height>480</height>
          <format>R8G8B8</format>
        </image>
        <clip>
          <near>0.02</near>
          <far>300</far>
        </clip>
        <noise>
          <type>gaussian</type>
          <mean>0.0</mean>
          <stddev>0.007</stddev>
        </noise>
      </camera>
      <plugin filename="libgazebo_ros_camera.so" name="camera_controller">
        <alwaysOn>true</alwaysOn>
        <updateRate>0.0</updateRate>
        <cameraName>car_model_camera</cameraName>
        <imageTopicName>image_raw</imageTopicName>
        <cameraInfoTopicName>camera_info</cameraInfoTopicName>
        <frameName>odom</frameName>
        <hackBaseline>0.07</hackBaseline>
        <distortionK1>0.0</distortionK1>
        <distortionK2>0.0</distortionK2>
        <distortionK3>0.0</distortionK3>
        <distortionT1>0.0</distortionT1>
        <distortionT2>0.0</distortionT2>
      </plugin>
    </sensor>
  </gazebo>
  <link name="front_axle">
    <visual>
      <geometry>
        <cylinder length="0.4" radius="0.0625"/>
      </geometry>
      <material name="gray"/>
    </visual>
    <collision>
      <geometry>
        <cylinder length="0.4" radius="0.0625"/>
      </geometry>
    </collision>
    <inertial>
      <mass value="10"/>
      <inertia ixx="1.0" ixy="0.0" ixz="0.0" iyy="1.0" iyz="0.0" izz="1.0"/>
    </inertial>
  </link>
  <joint name="front_axle_to_base" type="fixed">
    <axis xyz="1 0 0"/>
    <limit effort="1000.0" lower="-0.785" upper="0.785" velocity="1.0"/>
    <mimic joint="base_footprint_joint" multiplier="1"/>
    <parent link="base_footprint"/>
    <child link="front_axle"/>
    <origin rpy="0 -1.57 0" xyz="0 0.3 0.125"/>
  </joint>
  <gazebo reference="front_axle">
    <material>Gazebo/Grey</material>
  </gazebo>
  <link name="back_axle">
    <visual>
      <geometry>
        <cylinder length="0.4" radius="0.0625"/>
      </geometry>
      <material name="gray"/>
    </visual>
    <collision>
      <geometry>
        <cylinder length="0.4" radius="0.0625"/>
      </geometry>
    </collision>
    <inertial>
      <mass value="10"/>
      <inertia ixx="1.0" ixy="0.0" ixz="0.0" iyy="1.0" iyz="0.0" izz="1.0"/>
    </inertial>
  </link>
  <joint name="back_axle_to_base" type="fixed">
    <axis xyz="1 0 0"/>
    <limit effort="1000.0" lower="-0.785" upper="0.785" velocity="1.0"/>
    <mimic joint="base_footprint_joint" multiplier="1"/>
    <parent link="base_footprint"/>
    <child link="back_axle"/>
    <origin rpy="0 -1.57 0" xyz="0 -0.3 0.125"/>
  </joint>
  <gazebo reference="back_axle">
    <material>Gazebo/Grey</material>
  </gazebo>
  <link name="front_left_wheel">
    <visual>
      <geometry>
        <cylinder length="0.125" radius="0.125"/>
      </geometry>
      <material name="white"/>
    </visual>
    <collision>
      <geometry>
        <cylinder length="0.125" radius="0.125"/>
      </geometry>
    </collision>
    <inertial>
      <mass value="20"/>
      <inertia ixx="1.0" ixy="0.0" ixz="0.0" iyy="1.0" iyz="0.0" izz="1.0"/>
    </inertial>
  </link>
  <joint name="front_left_wheel_to_front_axle" type="revolute">
    <axis xyz="1 0 0"/>
    <limit effort="1000.0" lower="-0.393" upper="0.785" velocity="1.0"/>
    <parent link="base_footprint"/>
    <child link="front_left_wheel"/>
    <origin rpy="0 -1.57 0" xyz="-0.25 0.3 0.125"/>
  </joint>
  <transmission name="front_left_trans">
    <type>transmission_interface/SimpleTransmission</type>
    <actuator name="front_left_motor">
      <mechanicalReduction>1</mechanicalReduction>
    </actuator>
    <joint name="front_left_wheel_to_front_axle">
      <hardwareInterface>hardware_interface/PositionJointInterface</hardwareInterface>
    </joint>
  </transmission>
  <transmission name="front_left_vel_trans">
    <type>transmission_interface/SimpleTransmission</type>
    <actuator name="front_left_vel_motor">
      <mechanicalReduction>1</mechanicalReduction>
    </actuator>
    <joint name="front_left_wheel_to_front_axle">
      <hardwareInterface>hardware_interface/VelocityJointInterface</hardwareInterface>
    </joint>
  </transmission>
  <gazebo reference="front_left_wheel">
    <mu1 value="200.0"/>
    <mu2 value="100.0"/>
    <kp value="10000000.0"/>
    <kd value="1.0"/>
    <material>Gazebo/White</material>
  </gazebo>
  <link name="front_right_wheel">
    <visual>
      <geometry>
        <cylinder length="0.125" radius="0.125"/>
      </geometry>
      <material name="white"/>
    </visual>
    <collision>
      <geometry>
        <cylinder length="0.125" radius="0.125"/>
      </geometry>
    </collision>
    <inertial>
      <mass value="20"/>
      <inertia ixx="1.0" ixy="0.0" ixz="0.0" iyy="1.0" iyz="0.0" izz="1.0"/>
    </inertial>
  </link>
  <joint name="front_right_wheel_to_front_axle" type="revolute">
    <axis xyz="1 0 0"/>
    <limit effort="1000.0" lower="-0.785" upper="0.393" velocity="1.0"/>
    <parent link="base_footprint"/>
    <child link="front_right_wheel"/>
    <origin rpy="0 -1.57 0" xyz="0.25 0.3 0.125"/>
  </joint>
  <transmission name="front_right_trans">
    <type>transmission_interface/SimpleTransmission</type>
    <actuator name="front_right_motor">
      <mechanicalReduction>1</mechanicalReduction>
    </actuator>
    <joint name="front_right_wheel_to_front_axle">
      <hardwareInterface>hardware_interface/PositionJointInterface</hardwareInterface>
    </joint>
  </transmission>
  <transmission name="front_right_vel_trans">
    <type>transmission_interface/SimpleTransmission</type>
    <actuator name="front_right_vel_motor">
      <mechanicalReduction>1</mechanicalReduction>
    </actuator>
    <joint name="front_right_wheel_to_front_axle">
      <hardwareInterface>hardware_interface/VelocityJointInterface</hardwareInterface>
    </joint>
  </transmission>
  <gazebo reference="front_right_wheel">
    <mu1 value="200.0"/>
    <mu2 value="100.0"/>
    <kp value="10000000.0"/>
    <kd value="1.0"/>
    <material>Gazebo/White</material>
  </gazebo>
  <link name="back_left_wheel">
    <visual>
      <geometry>
        <cylinder length="0.125" radius="0.125"/>
      </geometry>
      <material name="white"/>
    </visual>
    <collision>
      <geometry>
        <cylinder length="0.125" radius="0.125"/>
      </geometry>
    </collision>
    <inertial>
      <mass value="20"/>
      <inertia ixx="1.0" ixy="0.0" ixz="0.0" iyy="1.0" iyz="0.0" izz="1.0"/>
    </inertial>
  </link>
  <joint name="back_left_wheel_to_back_axle" type="revolute">
    <axis xyz="0 0 1"/>
    <limit effort="1000.0" lower="-3140.0" upper="3140.0" velocity="1.0"/>
    <parent link="base_footprint"/>
    <child link="back_left_wheel"/>
    <origin rpy="0 -1.57 0" xyz="-0.25 -0.3 0.125"/>
  </joint>
  <transmission name="back_left_trans">
    <type>transmission_interface/SimpleTransmission</type>
    <actuator name="back_left_motor">
      <mechanicalReduction>1</mechanicalReduction>
    </actuator>
    <joint name="back_left_wheel_to_back_axle">
      <hardwareInterface>hardware_interface/PositionJointInterface</hardwareInterface>
    </joint>
  </transmission>
  <transmission name="back_left_vel_trans">
    <type>transmission_interface/SimpleTransmission</type>
    <actuator name="back_left_vel_motor">
      <mechanicalReduction>1</mechanicalReduction>
    </actuator>
    <joint name="back_left_wheel_to_back_axle">
      <hardwareInterface>hardware_interface/VelocityJointInterface</hardwareInterface>
    </joint>
  </transmission>
  <gazebo reference="back_left_wheel">
    <mu1 value="200.0"/>
    <mu2 value="100.0"/>
    <kp value="10000000.0"/>
    <kd value="1.0"/>
    <material>Gazebo/White</material>
  </gazebo>
  <link name="back_right_wheel">
    <visual>
      <geometry>
        <cylinder length="0.125" radius="0.125"/>
      </geometry>
      <material name="white"/>
    </visual>
    <collision>
      <geometry>
        <cylinder length="0.125" radius="0.125"/>
      </geometry>
    </collision>
    <inertial>
      <mass value="20"/>
      <inertia ixx="1.0" ixy="0.0" ixz="0.0" iyy="1.0" iyz="0.0" izz="1.0"/>
    </inertial>
  </link>
  <joint name="back_right_wheel_to_back_axle" type="revolute">
    <axis xyz="0 0 1"/>
    <limit effort="1000.0" lower="-3140.0" upper="3140.0" velocity="1.0"/>
    <parent link="base_footprint"/>
    <child link="back_right_wheel"/>
    <origin rpy="0 -1.57 0" xyz="0.25 -0.3 0.125"/>
  </joint>
  <transmission name="back_right_trans">
    <type>transmission_interface/SimpleTransmission</type>
    <actuator name="back_right_motor">
      <mechanicalReduction>1</mechanicalReduction>
    </actuator>
    <joint name="back_right_wheel_to_back_axle">
      <hardwareInterface>hardware_interface/PositionJointInterface</hardwareInterface>
    </joint>
  </transmission>
  <transmission name="back_right_vel_trans">
    <type>transmission_interface/SimpleTransmission</type>
    <actuator name="back_right_vel_motor">
      <mechanicalReduction>1</mechanicalReduction>
    </actuator>
    <joint name="back_right_wheel_to_back_axle">
      <hardwareInterface>hardware_interface/VelocityJointInterface</hardwareInterface>
    </joint>
  </transmission>
  <gazebo reference="back_right_wheel">
    <mu1 value="200.0"/>
    <mu2 value="100.0"/>
    <kp value="10000000.0"/>
    <kd value="1.0"/>
    <material>Gazebo/White</material>
  </gazebo>
  <!--
-->
  <gazebo>
    <!--
                <plugin name="gazebo_ros_control" filename="libgazebo_ros_control.so">
                        <robotNamespace>/</robotNamespace>
                </plugin>
-->
    <plugin filename="libgazebo_ros_diff_drive.so" name="differential_drive_controller">
      <alwaysOn>true</alwaysOn>
      <commandTopic>cmd_vel</commandTopic>
      <leftJoint>[front_left_wheel_to_front_axle, back_left_wheel_to_back_axle]</leftJoint>
      <legacyMode>false</legacyMode>
      <odometryFrame>odom</odometryFrame>
      <odometryTopic>odom</odometryTopic>
      <publishTf>100</publishTf>
      <publishWheelJointState>false</publishWheelJointState>
      <publishWheelTF>true</publishWheelTF>
      <rightJoint>[front_right_wheel_to_front_axle, back_right_wheel_to_back_axle]</rightJoint>
      <robotBaseFrame>base_link</robotBaseFrame>
      <robotNamespace>robot::base_footprint</robotNamespace>
      <rosDebugLevel>na</rosDebugLevel>
      <wheelTorque>5</wheelTorque>
      <updateRate>0.1</updateRate>
      <wheelAcceleration>2</wheelAcceleration>
      <wheelDiameter>0.25</wheelDiameter>
      <wheelSeparation>0.4</wheelSeparation>
    </plugin>
  </gazebo>
  <!--
        <leftJoint>front_right_wheel_to_front_axle</leftJoint>
        <rightJoint>front_left_wheel_to_front_axle</rightJoint>
        <leftJoint>back_right_wheel_to_back_axle</leftJoint>
        <rightJoint>back_left_wheel_to_back_axle</rightJoint>
        -->
</robot>

